Workbook

Sheet Chips
F1: Tournament Structure
F2: # Players | G2: 40 | H2: # Rebuys | I2: =G2/2 -> 20 | J2: # Total | K2: =ROUND(SUM(I2,G2),0) -> 60
B3: Colour | C3: Denomination | D3: Count | F3: Colour | G3: Denomination | H3: Count | I3: Value | J3: Total Chips rq'd | K3: Shortage
B4: White | C4: 25 | D4: 1295 | F4: White | G4: 25 | H4: 8 | I4: =Table116[[#This Row],[Denomination]]*Table116[[#This Row],[Count]] -> 200 | J4: =Table116[[#This Row],[Count]]*$K$2 -> 480 | K4: =MIN(D4-Table116[[#This Row],[Total Chips rq''d]],0) -> 0
B5: Red | C5: 100 | D5: 800 | F5: Red | G5: 100 | H5: 8 | I5: =Table116[[#This Row],[Denomination]]*Table116[[#This Row],[Count]] -> 800 | J5: =Table116[[#This Row],[Count]]*$K$2 -> 480 | K5: =MIN(D5-Table116[[#This Row],[Total Chips rq''d]],0) -> 0
B6: Green | C6: 500 | D6: 805 | F6: Green | G6: 500 | H6: 6 | I6: =Table116[[#This Row],[Denomination]]*Table116[[#This Row],[Count]] -> 3000 | J6: =Table116[[#This Row],[Count]]*$K$2 -> 360 | K6: =MIN(D6-Table116[[#This Row],[Total Chips rq''d]],0) -> 0
B7: Blue | C7: 1000 | D7: 813 | F7: Blue | G7: 1000 | H7: 4 | I7: =Table116[[#This Row],[Denomination]]*Table116[[#This Row],[Count]] -> 4000 | J7: =Table116[[#This Row],[Count]]*$K$2 -> 240 | K7: =MIN(D7-Table116[[#This Row],[Total Chips rq''d]],0) -> 0
B8: Black | C8: 5000 | D8: 806 | F8: Black | G8: 5000 | H8: 0 | I8: =Table116[[#This Row],[Denomination]]*Table116[[#This Row],[Count]] -> 0 | J8: =Table116[[#This Row],[Count]]*$K$2 -> 0 | K8: =MIN(D8-Table116[[#This Row],[Total Chips rq''d]],0) -> 0
F9: Total | H9: =SUBTOTAL(109,Table116[Count]) -> 26 | I9: =SUBTOTAL(109,Table116[Value]) -> 8000

Sheet Leadership
B2: Email | C2: Name | D2: Role
B3: dribkof@uwo.ca | C3: David Ribkoff | D3: President
B4: rchen496@uwo.ca | C4: Ryan Chen | D4: VP Comms
B5: mmacph52@uwo.ca | C5: Myles MacPherson | D5: VP Events
B6: tmah7@uwo.ca | C6: Tyler Mah | D6: VP External
B7: nfenske@uwo.ca | C7: Nathan Fenske | D7: VP Finance
B8: ycai388@uwo.ca | C8: Jackie Cai | D8: VP Projects
B9: edong23@uwo.ca | C9: Edward Dong | D9: Director of Events
B10: kali83@uwo.ca | C10: Kaden Ali | D10: Director of Events
B11: pzykmund@uwo.ca | C11: Pavel Zykmund | D11: Director of Events
B12: rshweiha@uwo.ca | C12: Rita Shweihat | D12: Director of Events
B13: sahn87@uwo.ca | C13: Sam Ahn | D13: Director of Events
C14: Matthew Barclay | D14: Director of Events
B15: lpanare@uwo.ca | C15: Leo Panarello | D15: Director of External
B16: akwong45@uwo.ca | C16: Aidan Kwong | D16: Director of Finance
B17: ezavedei@uwo.ca | C17: Eduard Zavedei | D17: Director of Graphics
B18: oacheamp@uwo.ca | C18: Ohemaa Acheampong | D18: Director of Graphics
B19: bbulyovs@uwo.ca | C19: Ben Bulyovsky | D19: Director of Productions
B20: ckernag@uwo.ca | C20: Charlie Kernaghan | D20: Director of Productions
B21: bsuidgee@uwo.ca | C21: Brock Suidgeest | D21: Director of Projects
B22: cbechtol@uwo.ca | C22: Cyrus Bechtold | D22: Director of Projects
B23: jouyan26@uwo.ca | C23: Jillian Ouyang | D23: Director of Projects
B24: rmandi@uwo.ca | C24: Rohan Mandi | D24: Director of Projects
B25: ekim455@uwo.ca | C25: Ethan Kim | D25: Director of Sponsorships
B26: ksee3@uwo.ca | C26: Kyler See | D26: Director of Sponsorships
... B75: zhao49@uwo.ca | C75: Zack Hao | D75: Executive
B76: Total | D76: =SUBTOTAL(103,Table26[Role]) -> 73

Sheet Structures
G1: =TODAY() -> 46092
B2: Rank | C2: Ref | D2: Points | E2: Points w/ Rebuy | M2: Boolean | O2: Tournament Dates | Q2: Year of study | S2: Program | U2: Membership | W2: Rank | Y2: Role
B3: 1 | D3: 50 | E3: =ROUNDUP(D3*0.75,0) -> 38 | M3: Yes | O3: 45930 | Q3: 1 | S3: Don Wright Faculty of Music | U3: Verified | W3: Gold | Y3: President
B4: 2 | D4: 30 | E4: =ROUNDUP(D4*0.75,0) -> 23 | M4: No | O4: 45932 | Q4: 2 | S4: Faculty of Arts and Humanities | U4: Unverified | W4: Silver | Y4: VP
B5: 3 | D5: 20 | E5: =ROUNDUP(D5*0.75,0) -> 15 | G5: Name | H5: All-time rank | I5: All-time score | J5: Helper | K5: Helper2 | M5: DNP | O5: 45939 | Q5: 3 | S5: Faculty of Education | W5: Bronze | Y5: Director
B6: Final Table | C6: 10 | D6: 10 | E6: =ROUNDUP(D6*0.75,0) -> 8 | G6: =IFERROR(Table5[[#This Row],[Full name]],"") -> David Ribkoff | H6: =_xlfn.RANK.EQ(AllTime1[[#This Row],[All-time score]],AllTime1[All-time score],0) -> 83 | I6: =_xlfn.XLOOKUP(AllTime1[[#This Row],[Name]],Table16[Name],Table16[Totals],"Error",0,1) -> 20 | J6: =IF(ISNUMBER(AllTime1[[#This Row],[All-time rank]]), AllTime1[[#This Row],[All-time rank]] + ROW(AllTime1[[#This Row],[All-time rank]])/100000, 99999 + ROW(AllTime1[[#This Row],[All-time rank]])/100000) -> 83.00006 | K6: =IF(ISNUMBER(AllTime1[[#This Row],[All-time score]]), AllTime1[[#This Row],[All-time score]] + ROW(AllTime1[[#This Row],[All-time score]])/100000000, 0 + ROW(AllTime1[[#This Row],[All-time score]])/1000000000) -> 20 | O6: 45944 | Q6: 4 | S6: Faculty of Engineering | W6: 4th | Y6: President
B7: Top Quartile | C7: 0.25 | D7: 4 | E7: =ROUNDUP(D7*0.75,0) -> 3 | G7: =IFERROR(Table5[[#This Row],[Full name]],"") -> Ryan Chen | H7: =_xlfn.RANK.EQ(AllTime1[[#This Row],[All-time score]],AllTime1[All-time score],0) -> 45 | I7: =_xlfn.XLOOKUP(AllTime1[[#This Row],[Name]],Table16[Name],Table16[Totals],"Error",0,1) -> 34 | J7: =IF(ISNUMBER(AllTime1[[#This Row],[All-time rank]]), AllTime1[[#This Row],[All-time rank]] + ROW(AllTime1[[#This Row],[All-time rank]])/100000, 99999 + ROW(AllTime1[[#This Row],[All-time rank]])/100000) -> 45.00007 | K7: =IF(ISNUMBER(AllTime1[[#This Row],[All-time score]]), AllTime1[[#This Row],[All-time score]] + ROW(AllTime1[[#This Row],[All-time score]])/100000000, 0 + ROW(AllTime1[[#This Row],[All-time score]])/1000000000) -> 34 | O7: 45953 | Q7: 5+ | S7: Faculty of Health Sciences | W7: 5th
B8: Top Half | C8: 0.5 | D8: 2 | E8: =ROUNDUP(D8*0.75,0) -> 2 | G8: =IFERROR(Table5[[#This Row],[Full name]],"") -> Myles MacPherson | H8: =_xlfn.RANK.EQ(AllTime1[[#This Row],[All-time score]],AllTime1[All-time score],0) -> 165 | I8: =_xlfn.XLOOKUP(AllTime1[[#This Row],[Name]],Table16[Name],Table16[Totals],"Error",0,1) -> 5 | J8: =IF(ISNUMBER(AllTime1[[#This Row],[All-time rank]]), AllTime1[[#This Row],[All-time rank]] + ROW(AllTime1[[#This Row],[All-time rank]])/100000, 99999 + ROW(AllTime1[[#This Row],[All-time rank]])/100000) -> 165.00008 | K8: =IF(ISNUMBER(AllTime1[[#This Row],[All-time score]]), AllTime1[[#This Row],[All-time score]] + ROW(AllTime1[[#This Row],[All-time score]])/100000000, 0 + ROW(AllTime1[[#This Row],[All-time score]])/1000000000) -> 5.0000001 | O8: 45958 | Q8: Master's or PhD | S8: Faculty of Information and Media Studies | W8: 6th
B9: Participation | C9: 1 | D9: 1 | E9: =ROUNDUP(D9*0.75,0) -> 1 | G9: =IFERROR(Table5[[#This Row],[Full name]],"") -> Tyler Mah | H9: =_xlfn.RANK.EQ(AllTime1[[#This Row],[All-time score]],AllTime1[All-time score],0) -> 113 | I9: =_xlfn.XLOOKUP(AllTime1[[#This Row],[Name]],Table16[Name],Table16[Totals],"Error",0,1) -> 13 | J9: =IF(ISNUMBER(AllTime1[[#This Row],[All-time rank]]), AllTime1[[#This Row],[All-time rank]] + ROW(AllTime1[[#This Row],[All-time rank]])/100000, 99999 + ROW(AllTime1[[#This Row],[All-time rank]])/100000) -> 113.00009 | K9: =IF(ISNUMBER(AllTime1[[#This Row],[All-time score]]), AllTime1[[#This Row],[All-time score]] + ROW(AllTime1[[#This Row],[All-time score]])/100000000, 0 + ROW(AllTime1[[#This Row],[All-time score]])/1000000000) -> 13 | O9: 45974 | S9: Faculty of Law | W9: 7th
G10: =IFERROR(Table5[[#This Row],[Full name]],"") -> Nathan Fenske | H10: =_xlfn.RANK.EQ(AllTime1[[#This Row],[All-time score]],AllTime1[All-time score],0) -> 198 | I10: =_xlfn.XLOOKUP(AllTime1[[#This Row],[Name]],Table16[Name],Table16[Totals],"Error",0,1) -> 3 | J10: =IF(ISNUMBER(AllTime1[[#This Row],[All-time rank]]), AllTime1[[#This Row],[All-time rank]] + ROW(AllTime1[[#This Row],[All-time rank]])/100000, 99999 + ROW(AllTime1[[#This Row],[All-time rank]])/100000) -> 198.0001 | K10: =IF(ISNUMBER(AllTime1[[#This Row],[All-time score]]), AllTime1[[#This Row],[All-time score]] + ROW(AllTime1[[#This Row],[All-time score]])/100000000, 0 + ROW(AllTime1[[#This Row],[All-time score]])/1000000000) -> 3.0000001 | O10: 45979 | S10: Faculty of Science | W10: 8th
G11: =IFERROR(Table5[[#This Row],[Full name]],"") -> Jackie Cai | H11: =_xlfn.RANK.EQ(AllTime1[[#This Row],[All-time score]],AllTime1[All-time score],0) -> 80 | I11: =_xlfn.XLOOKUP(AllTime1[[#This Row],[Name]],Table16[Name],Table16[Totals],"Error",0,1) -> 21 | J11: =IF(ISNUMBER(AllTime1[[#This Row],[All-time rank]]), AllTime1[[#This Row],[All-time rank]] + ROW(AllTime1[[#This Row],[All-time rank]])/100000, 99999 + ROW(AllTime1[[#This Row],[All-time rank]])/100000) -> 80.00011 | K11: =IF(ISNUMBER(AllTime1[[#This Row],[All-time score]]), AllTime1[[#This Row],[All-time score]] + ROW(AllTime1[[#This Row],[All-time score]])/100000000, 0 + ROW(AllTime1[[#This Row],[All-time score]])/1000000000) -> 21 | O11: 45981 | S11: Faculty of Social Science | W11: 9th
G12: =IFERROR(Table5[[#This Row],[Full name]],"") -> Edward Dong | H12: =_xlfn.RANK.EQ(AllTime1[[#This Row],[All-time score]],AllTime1[All-time score],0) -> 100 | I12: =_xlfn.XLOOKUP(AllTime1[[#This Row],[Name]],Table16[Name],Table16[Totals],"Error",0,1) -> 15 | J12: =IF(ISNUMBER(AllTime1[[#This Row],[All-time rank]]), AllTime1[[#This Row],[All-time rank]] + ROW(AllTime1[[#This Row],[All-time rank]])/100000, 99999 + ROW(AllTime1[[#This Row],[All-time rank]])/100000) -> 100.00012 | K12: =IF(ISNUMBER(AllTime1[[#This Row],[All-time score]]), AllTime1[[#This Row],[All-time score]] + ROW(AllTime1[[#This Row],[All-time score]])/100000000, 0 + ROW(AllTime1[[#This Row],[All-time score]])/1000000000) -> 15 | O12: 45988 | S12: Huron Arts & Social Science | W12: 10th
G13: =IFERROR(Table5[[#This Row],[Full name]],"") -> Kaden Ali | H13: =_xlfn.RANK.EQ(AllTime1[[#This Row],[All-time score]],AllTime1[All-time score],0) -> 113 | I13: =_xlfn.XLOOKUP(AllTime1[[#This Row],[Name]],Table16[Name],Table16[Totals],"Error",0,1) -> 13 | J13: =IF(ISNUMBER(AllTime1[[#This Row],[All-time rank]]), AllTime1[[#This Row],[All-time rank]] + ROW(AllTime1[[#This Row],[All-time rank]])/100000, 99999 + ROW(AllTime1[[#This Row],[All-time rank]])/100000) -> 113.00013 | K13: =IF(ISNUMBER(AllTime1[[#This Row],[All-time score]]), AllTime1[[#This Row],[All-time score]] + ROW(AllTime1[[#This Row],[All-time score]])/100000000, 0 + ROW(AllTime1[[#This Row],[All-time score]])/1000000000) -> 13 | O13: 45993 | S13: Huron MOS
G14: =IFERROR(Table5[[#This Row],[Full name]],"") -> Matthew Barclay | H14: =_xlfn.RANK.EQ(AllTime1[[#This Row],[All-time score]],AllTime1[All-time score],0) -> 22 | I14: =_xlfn.XLOOKUP(AllTime1[[#This Row],[Name]],Table16[Name],Table16[Totals],"Error",0,1) -> 57 | J14: =IF(ISNUMBER(AllTime1[[#This Row],[All-time rank]]), AllTime1[[#This Row],[All-time rank]] + ROW(AllTime1[[#This Row],[All-time rank]])/100000, 99999 + ROW(AllTime1[[#This Row],[All-time rank]])/100000) -> 22.00014 | K14: =IF(ISNUMBER(AllTime1[[#This Row],[All-time score]]), AllTime1[[#This Row],[All-time score]] + ROW(AllTime1[[#This Row],[All-time score]])/100000000, 0 + ROW(AllTime1[[#This Row],[All-time score]])/1000000000) -> 57 | O14: 46049 | S14: Huron Theology
G15: =IFERROR(Table5[[#This Row],[Full name]],"") -> Pavel Zykmund | H15: =_xlfn.RANK.EQ(AllTime1[[#This Row],[All-time score]],AllTime1[All-time score],0) -> 14 | I15: =_xlfn.XLOOKUP(AllTime1[[#This Row],[Name]],Table16[Name],Table16[Totals],"Error",0,1) -> 66 | J15: =IF(ISNUMBER(AllTime1[[#This Row],[All-time rank]]), AllTime1[[#This Row],[All-time rank]] + ROW(AllTime1[[#This Row],[All-time rank]])/100000, 99999 + ROW(AllTime1[[#This Row],[All-time rank]])/100000) -> 14.00015 | K15: =IF(ISNUMBER(AllTime1[[#This Row],[All-time score]]), AllTime1[[#This Row],[All-time score]] + ROW(AllTime1[[#This Row],[All-time score]])/100000000, 0 + ROW(AllTime1[[#This Row],[All-time score]])/1000000000) -> 66 | O15: 46051 | S15: King's Social Sciences
G16: =IFERROR(Table5[[#This Row],[Full name]],"") -> Rita Shweihat | H16: =_xlfn.RANK.EQ(AllTime1[[#This Row],[All-time score]],AllTime1[All-time score],0) -> 96 | I16: =_xlfn.XLOOKUP(AllTime1[[#This Row],[Name]],Table16[Name],Table16[Totals],"Error",0,1) -> 16 | J16: =IF(ISNUMBER(AllTime1[[#This Row],[All-time rank]]), AllTime1[[#This Row],[All-time rank]] + ROW(AllTime1[[#This Row],[All-time rank]])/100000, 99999 + ROW(AllTime1[[#This Row],[All-time rank]])/100000) -> 96.00016 | K16: =IF(ISNUMBER(AllTime1[[#This Row],[All-time score]]), AllTime1[[#This Row],[All-time score]] + ROW(AllTime1[[#This Row],[All-time score]])/100000000, 0 + ROW(AllTime1[[#This Row],[All-time score]])/1000000000) -> 16 | O16: 46056 | S16: King's Arts & Humanities
G17: =IFERROR(Table5[[#This Row],[Full name]],"") -> Sam Ahn | H17: =_xlfn.RANK.EQ(AllTime1[[#This Row],[All-time score]],AllTime1[All-time score],0) -> 1 | I17: =_xlfn.XLOOKUP(AllTime1[[#This Row],[Name]],Table16[Name],Table16[Totals],"Error",0,1) -> 216 | J17: =IF(ISNUMBER(AllTime1[[#This Row],[All-time rank]]), AllTime1[[#This Row],[All-time rank]] + ROW(AllTime1[[#This Row],[All-time rank]])/100000, 99999 + ROW(AllTime1[[#This Row],[All-time rank]])/100000) -> 1.00017 | K17: =IF(ISNUMBER(AllTime1[[#This Row],[All-time score]]), AllTime1[[#This Row],[All-time score]] + ROW(AllTime1[[#This Row],[All-time score]])/100000000, 0 + ROW(AllTime1[[#This Row],[All-time score]])/1000000000) -> 216 | O17: 46058 | S17: King's MOS
G18: =IFERROR(Table5[[#This Row],[Full name]],"") -> Aidan Kwong | H18: =_xlfn.RANK.EQ(AllTime1[[#This Row],[All-time score]],AllTime1[All-time score],0) -> 22 | I18: =_xlfn.XLOOKUP(AllTime1[[#This Row],[Name]],Table16[Name],Table16[Totals],"Error",0,1) -> 57 | J18: =IF(ISNUMBER(AllTime1[[#This Row],[All-time rank]]), AllTime1[[#This Row],[All-time rank]] + ROW(AllTime1[[#This Row],[All-time rank]])/100000, 99999 + ROW(AllTime1[[#This Row],[All-time rank]])/100000) -> 22.00018 | K18: =IF(ISNUMBER(AllTime1[[#This Row],[All-time score]]), AllTime1[[#This Row],[All-time score]] + ROW(AllTime1[[#This Row],[All-time score]])/100000000, 0 + ROW(AllTime1[[#This Row],[All-time score]])/1000000000) -> 57 | O18: 46063 | S18: King's Economics and Finance
G19: =IFERROR(Table5[[#This Row],[Full name]],"") -> Eduard Zavedei | H19: =_xlfn.RANK.EQ(AllTime1[[#This Row],[All-time score]],AllTime1[All-time score],0) -> 220 | I19: =_xlfn.XLOOKUP(AllTime1[[#This Row],[Name]],Table16[Name],Table16[Totals],"Error",0,1) -> 2 | J19: =IF(ISNUMBER(AllTime1[[#This Row],[All-time rank]]), AllTime1[[#This Row],[All-time rank]] + ROW(AllTime1[[#This Row],[All-time rank]])/100000, 99999 + ROW(AllTime1[[#This Row],[All-time rank]])/100000) -> 220.00019 | K19: =IF(ISNUMBER(AllTime1[[#This Row],[All-time score]]), AllTime1[[#This Row],[All-time score]] + ROW(AllTime1[[#This Row],[All-time score]])/100000000, 0 + ROW(AllTime1[[#This Row],[All-time score]])/1000000000) -> 2.0000002 | O19: 46065 | S19: King's Mathematics and Statistics
G20: =IFERROR(Table5[[#This Row],[Full name]],"") -> Ohemaa Acheampong | H20: =_xlfn.RANK.EQ(AllTime1[[#This Row],[All-time score]],AllTime1[All-time score],0) -> 248 | I20: =_xlfn.XLOOKUP(AllTime1[[#This Row],[Name]],Table16[Name],Table16[Totals],"Error",0,1) -> 1 | J20: =IF(ISNUMBER(AllTime1[[#This Row],[All-time rank]]), AllTime1[[#This Row],[All-time rank]] + ROW(AllTime1[[#This Row],[All-time rank]])/100000, 99999 + ROW(AllTime1[[#This Row],[All-time rank]])/100000) -> 248.0002 | K20: =IF(ISNUMBER(AllTime1[[#This Row],[All-time score]]), AllTime1[[#This Row],[All-time score]] + ROW(AllTime1[[#This Row],[All-time score]])/100000000, 0 + ROW(AllTime1[[#This Row],[All-time score]])/1000000000) -> 1.0000002 | O20: 46077 | S20: Richard Ivey School Of Business
G21: =IFERROR(Table5[[#This Row],[Full name]],"") -> Ben Bulyovsky | H21: =_xlfn.RANK.EQ(AllTime1[[#This Row],[All-time score]],AllTime1[All-time score],0) -> 177 | I21: =_xlfn.XLOOKUP(AllTime1[[#This Row],[Name]],Table16[Name],Table16[Totals],"Error",0,1) -> 4 | J21: =IF(ISNUMBER(AllTime1[[#This Row],[All-time rank]]), AllTime1[[#This Row],[All-time rank]] + ROW(AllTime1[[#This Row],[All-time rank]])/100000, 99999 + ROW(AllTime1[[#This Row],[All-time rank]])/100000) -> 177.00021 | K21: =IF(ISNUMBER(AllTime1[[#This Row],[All-time score]]), AllTime1[[#This Row],[All-time score]] + ROW(AllTime1[[#This Row],[All-time score]])/100000000, 0 + ROW(AllTime1[[#This Row],[All-time score]])/1000000000) -> 4.0000002 | O21: 46079 | S21: Schulich School of Medicine & Dentistry
G22: =IFERROR(Table5[[#This Row],[Full name]],"") -> Brock Suidgeest | H22: =_xlfn.RANK.EQ(AllTime1[[#This Row],[All-time score]],AllTime1[All-time score],0) -> 113 | I22: =_xlfn.XLOOKUP(AllTime1[[#This Row],[Name]],Table16[Name],Table16[Totals],"Error",0,1) -> 13 | J22: =IF(ISNUMBER(AllTime1[[#This Row],[All-time rank]]), AllTime1[[#This Row],[All-time rank]] + ROW(AllTime1[[#This Row],[All-time rank]])/100000, 99999 + ROW(AllTime1[[#This Row],[All-time rank]])/100000) -> 113.00022 | K22: =IF(ISNUMBER(AllTime1[[#This Row],[All-time score]]), AllTime1[[#This Row],[All-time score]] + ROW(AllTime1[[#This Row],[All-time score]])/100000000, 0 + ROW(AllTime1[[#This Row],[All-time score]])/1000000000) -> 13 | O22: 46084 | S22: Western, Brescia Modules/Programs
G23: =IFERROR(Table5[[#This Row],[Full name]],"") -> Cyrus Bechtold | H23: =_xlfn.RANK.EQ(AllTime1[[#This Row],[All-time score]],AllTime1[All-time score],0) -> 67 | I23: =_xlfn.XLOOKUP(AllTime1[[#This Row],[Name]],Table16[Name],Table16[Totals],"Error",0,1) -> 24 | J23: =IF(ISNUMBER(AllTime1[[#This Row],[All-time rank]]), AllTime1[[#This Row],[All-time rank]] + ROW(AllTime1[[#This Row],[All-time rank]])/100000, 99999 + ROW(AllTime1[[#This Row],[All-time rank]])/100000) -> 67.00023 | K23: =IF(ISNUMBER(AllTime1[[#This Row],[All-time score]]), AllTime1[[#This Row],[All-time score]] + ROW(AllTime1[[#This Row],[All-time score]])/100000000, 0 + ROW(AllTime1[[#This Row],[All-time score]])/1000000000) -> 24 | O23: 46086 | S23: Western, Scholars Programs
G24: =IFERROR(Table5[[#This Row],[Full name]],"") -> Jillian Ouyang | H24: =_xlfn.RANK.EQ(AllTime1[[#This Row],[All-time score]],AllTime1[All-time score],0) -> 147 | I24: =_xlfn.XLOOKUP(AllTime1[[#This Row],[Name]],Table16[Name],Table16[Totals],"Error",0,1) -> 9 | J24: =IF(ISNUMBER(AllTime1[[#This Row],[All-time rank]]), AllTime1[[#This Row],[All-time rank]] + ROW(AllTime1[[#This Row],[All-time rank]])/100000, 99999 + ROW(AllTime1[[#This Row],[All-time rank]])/100000) -> 147.00024 | K24: =IF(ISNUMBER(AllTime1[[#This Row],[All-time score]]), AllTime1[[#This Row],[All-time score]] + ROW(AllTime1[[#This Row],[All-time score]])/100000000, 0 + ROW(AllTime1[[#This Row],[All-time score]])/1000000000) -> 9.0000002 | O24: 46091
G25: =IFERROR(Table5[[#This Row],[Full name]],"") -> Rohan Mandi | H25: =_xlfn.RANK.EQ(AllTime1[[#This Row],[All-time score]],AllTime1[All-time score],0) -> 87 | I25: =_xlfn.XLOOKUP(AllTime1[[#This Row],[Name]],Table16[Name],Table16[Totals],"Error",0,1) -> 18 | J25: =IF(ISNUMBER(AllTime1[[#This Row],[All-time rank]]), AllTime1[[#This Row],[All-time rank]] + ROW(AllTime1[[#This Row],[All-time rank]])/100000, 99999 + ROW(AllTime1[[#This Row],[All-time rank]])/100000) -> 87.00025 | K25: =IF(ISNUMBER(AllTime1[[#This Row],[All-time score]]), AllTime1[[#This Row],[All-time score]] + ROW(AllTime1[[#This Row],[All-time score]])/100000000, 0 + ROW(AllTime1[[#This Row],[All-time score]])/1000000000) -> 18 | O25: 46093
G26: =IFERROR(Table5[[#This Row],[Full name]],"") -> Ethan Kim | H26: =_xlfn.RANK.EQ(AllTime1[[#This Row],[All-time score]],AllTime1[All-time score],0) -> 248 | I26: =_xlfn.XLOOKUP(AllTime1[[#This Row],[Name]],Table16[Name],Table16[Totals],"Error",0,1) -> 1 | J26: =IF(ISNUMBER(AllTime1[[#This Row],[All-time rank]]), AllTime1[[#This Row],[All-time rank]] + ROW(AllTime1[[#This Row],[All-time rank]])/100000, 99999 + ROW(AllTime1[[#This Row],[All-time rank]])/100000) -> 248.00026 | K26: =IF(ISNUMBER(AllTime1[[#This Row],[All-time score]]), AllTime1[[#This Row],[All-time score]] + ROW(AllTime1[[#This Row],[All-time score]])/100000000, 0 + ROW(AllTime1[[#This Row],[All-time score]])/1000000000) -> 1.0000003 | O26: 46098
G27: =IFERROR(Table5[[#This Row],[Full name]],"") -> Kyler See | H27: =_xlfn.RANK.EQ(AllTime1[[#This Row],[All-time score]],AllTime1[All-time score],0) -> 198 | I27: =_xlfn.XLOOKUP(AllTime1[[#This Row],[Name]],Table16[Name],Table16[Totals],"Error",0,1) -> 3 | J27: =IF(ISNUMBER(AllTime1[[#This Row],[All-time rank]]), AllTime1[[#This Row],[All-time rank]] + ROW(AllTime1[[#This Row],[All-time rank]])/100000, 99999 + ROW(AllTime1[[#This Row],[All-time rank]])/100000) -> 198.00027 | K27: =IF(ISNUMBER(AllTime1[[#This Row],[All-time score]]), AllTime1[[#This Row],[All-time score]] + ROW(AllTime1[[#This Row],[All-time score]])/100000000, 0 + ROW(AllTime1[[#This Row],[All-time score]])/1000000000) -> 3.0000003 | O27: 46100
G28: =IFERROR(Table5[[#This Row],[Full name]],"") -> Aaron Kara | H28: =_xlfn.RANK.EQ(AllTime1[[#This Row],[All-time score]],AllTime1[All-time score],0) -> 159 | I28: =_xlfn.XLOOKUP(AllTime1[[#This Row],[Name]],Table16[Name],Table16[Totals],"Error",0,1) -> 6 | J28: =IF(ISNUMBER(AllTime1[[#This Row],[All-time rank]]), AllTime1[[#This Row],[All-time rank]] + ROW(AllTime1[[#This Row],[All-time rank]])/100000, 99999 + ROW(AllTime1[[#This Row],[All-time rank]])/100000) -> 159.00028 | K28: =IF(ISNUMBER(AllTime1[[#This Row],[All-time score]]), AllTime1[[#This Row],[All-time score]] + ROW(AllTime1[[#This Row],[All-time score]])/100000000, 0 + ROW(AllTime1[[#This Row],[All-time score]])/1000000000) -> 6.0000003 | O28: 46105
G29: =IFERROR(Table5[[#This Row],[Full name]],"") -> Aiden Ko | H29: =_xlfn.RANK.EQ(AllTime1[[#This Row],[All-time score]],AllTime1[All-time score],0) -> 300 | I29: =_xlfn.XLOOKUP(AllTime1[[#This Row],[Name]],Table16[Name],Table16[Totals],"Error",0,1) -> 0 | J29: =IF(ISNUMBER(AllTime1[[#This Row],[All-time rank]]), AllTime1[[#This Row],[All-time rank]] + ROW(AllTime1[[#This Row],[All-time rank]])/100000, 99999 + ROW(AllTime1[[#This Row],[All-time rank]])/100000) -> 300.00029 | K29: =IF(ISNUMBER(AllTime1[[#This Row],[All-time score]]), AllTime1[[#This Row],[All-time score]] + ROW(AllTime1[[#This Row],[All-time score]])/100000000, 0 + ROW(AllTime1[[#This Row],[All-time score]])/1000000000) -> 2.9e-07 | O29: 46107
G30: =IFERROR(Table5[[#This Row],[Full name]],"") -> Allen Liu | H30: =_xlfn.RANK.EQ(AllTime1[[#This Row],[All-time score]],AllTime1[All-time score],0) -> 57 | I30: =_xlfn.XLOOKUP(AllTime1[[#This Row],[Name]],Table16[Name],Table16[Totals],"Error",0,1) -> 28 | J30: =IF(ISNUMBER(AllTime1[[#This Row],[All-time rank]]), AllTime1[[#This Row],[All-time rank]] + ROW(AllTime1[[#This Row],[All-time rank]])/100000, 99999 + ROW(AllTime1[[#This Row],[All-time rank]])/100000) -> 57.0003 | K30: =IF(ISNUMBER(AllTime1[[#This Row],[All-time score]]), AllTime1[[#This Row],[All-time score]] + ROW(AllTime1[[#This Row],[All-time score]])/100000000, 0 + ROW(AllTime1[[#This Row],[All-time score]])/1000000000) -> 28 | O30: 46112
G31: =IFERROR(Table5[[#This Row],[Full name]],"") -> Aman Bains | H31: =_xlfn.RANK.EQ(AllTime1[[#This Row],[All-time score]],AllTime1[All-time score],0) -> 300 | I31: =_xlfn.XLOOKUP(AllTime1[[#This Row],[Name]],Table16[Name],Table16[Totals],"Error",0,1) -> 0 | J31: =IF(ISNUMBER(AllTime1[[#This Row],[All-time rank]]), AllTime1[[#This Row],[All-time rank]] + ROW(AllTime1[[#This Row],[All-time rank]])/100000, 99999 + ROW(AllTime1[[#This Row],[All-time rank]])/100000) -> 300.00031 | K31: =IF(ISNUMBER(AllTime1[[#This Row],[All-time score]]), AllTime1[[#This Row],[All-time score]] + ROW(AllTime1[[#This Row],[All-time score]])/100000000, 0 + ROW(AllTime1[[#This Row],[All-time score]])/1000000000) -> 3.1e-07 | O31: 46114
G32: =IFERROR(Table5[[#This Row],[Full name]],"") -> Anna Yu | H32: =_xlfn.RANK.EQ(AllTime1[[#This Row],[All-time score]],AllTime1[All-time score],0) -> 55 | I32: =_xlfn.XLOOKUP(AllTime1[[#This Row],[Name]],Table16[Name],Table16[Totals],"Error",0,1) -> 29 | J32: =IF(ISNUMBER(AllTime1[[#This Row],[All-time rank]]), AllTime1[[#This Row],[All-time rank]] + ROW(AllTime1[[#This Row],[All-time rank]])/100000, 99999 + ROW(AllTime1[[#This Row],[All-time rank]])/100000) -> 55.00032 | K32: =IF(ISNUMBER(AllTime1[[#This Row],[All-time score]]), AllTime1[[#This Row],[All-time score]] + ROW(AllTime1[[#This Row],[All-time score]])/100000000, 0 + ROW(AllTime1[[#This Row],[All-time score]])/1000000000) -> 29 | O32: 46119
G33: =IFERROR(Table5[[#This Row],[Full name]],"") -> Carson Cull | H33: =_xlfn.RANK.EQ(AllTime1[[#This Row],[All-time score]],AllTime1[All-time score],0) -> 100 | I33: =_xlfn.XLOOKUP(AllTime1[[#This Row],[Name]],Table16[Name],Table16[Totals],"Error",0,1) -> 15 | J33: =IF(ISNUMBER(AllTime1[[#This Row],[All-time rank]]), AllTime1[[#This Row],[All-time rank]] + ROW(AllTime1[[#This Row],[All-time rank]])/100000, 99999 + ROW(AllTime1[[#This Row],[All-time rank]])/100000) -> 100.00033 | K33: =IF(ISNUMBER(AllTime1[[#This Row],[All-time score]]), AllTime1[[#This Row],[All-time score]] + ROW(AllTime1[[#This Row],[All-time score]])/100000000, 0 + ROW(AllTime1[[#This Row],[All-time score]])/1000000000) -> 15 | O33: 46121
G34: =IFERROR(Table5[[#This Row],[Full name]],"") -> Cole Eisen | H34: =_xlfn.RANK.EQ(AllTime1[[#This Row],[All-time score]],AllTime1[All-time score],0) -> 159 | I34: =_xlfn.XLOOKUP(AllTime1[[#This Row],[Name]],Table16[Name],Table16[Totals],"Error",0,1) -> 6 | J34: =IF(ISNUMBER(AllTime1[[#This Row],[All-time rank]]), AllTime1[[#This Row],[All-time rank]] + ROW(AllTime1[[#This Row],[All-time rank]])/100000, 99999 + ROW(AllTime1[[#This Row],[All-time rank]])/100000) -> 159.00034 | K34: =IF(ISNUMBER(AllTime1[[#This Row],[All-time score]]), AllTime1[[#This Row],[All-time score]] + ROW(AllTime1[[#This Row],[All-time score]])/100000000, 0 + ROW(AllTime1[[#This Row],[All-time score]])/1000000000) -> 6.0000003
G35: =IFERROR(Table5[[#This Row],[Full name]],"") -> Cole Korchinski | H35: =_xlfn.RANK.EQ(AllTime1[[#This Row],[All-time score]],AllTime1[All-time score],0) -> 154 | I35: =_xlfn.XLOOKUP(AllTime1[[#This Row],[Name]],Table16[Name],Table16[Totals],"Error",0,1) -> 8 | J35: =IF(ISNUMBER(AllTime1[[#This Row],[All-time rank]]), AllTime1[[#This Row],[All-time rank]] + ROW(AllTime1[[#This Row],[All-time rank]])/100000, 99999 + ROW(AllTime1[[#This Row],[All-time rank]])/100000) -> 154.00035 | K35: =IF(ISNUMBER(AllTime1[[#This Row],[All-time score]]), AllTime1[[#This Row],[All-time score]] + ROW(AllTime1[[#This Row],[All-time score]])/100000000, 0 + ROW(AllTime1[[#This Row],[All-time score]])/1000000000) -> 8.0000004
G36: =IFERROR(Table5[[#This Row],[Full name]],"") -> Damon Deng | H36: =_xlfn.RANK.EQ(AllTime1[[#This Row],[All-time score]],AllTime1[All-time score],0) -> 57 | I36: =_xlfn.XLOOKUP(AllTime1[[#This Row],[Name]],Table16[Name],Table16[Totals],"Error",0,1) -> 28 | J36: =IF(ISNUMBER(AllTime1[[#This Row],[All-time rank]]), AllTime1[[#This Row],[All-time rank]] + ROW(AllTime1[[#This Row],[All-time rank]])/100000, 99999 + ROW(AllTime1[[#This Row],[All-time rank]])/100000) -> 57.00036 | K36: =IF(ISNUMBER(AllTime1[[#This Row],[All-time score]]), AllTime1[[#This Row],[All-time score]] + ROW(AllTime1[[#This Row],[All-time score]])/100000000, 0 + ROW(AllTime1[[#This Row],[All-time score]])/1000000000) -> 28
G37: =IFERROR(Table5[[#This Row],[Full name]],"") -> Daniel Dillabough | H37: =_xlfn.RANK.EQ(AllTime1[[#This Row],[All-time score]],AllTime1[All-time score],0) -> 113 | I37: =_xlfn.XLOOKUP(AllTime1[[#This Row],[Name]],Table16[Name],Table16[Totals],"Error",0,1) -> 13 | J37: =IF(ISNUMBER(AllTime1[[#This Row],[All-time rank]]), AllTime1[[#This Row],[All-time rank]] + ROW(AllTime1[[#This Row],[All-time rank]])/100000, 99999 + ROW(AllTime1[[#This Row],[All-time rank]])/100000) -> 113.00037 | K37: =IF(ISNUMBER(AllTime1[[#This Row],[All-time score]]), AllTime1[[#This Row],[All-time score]] + ROW(AllTime1[[#This Row],[All-time score]])/100000000, 0 + ROW(AllTime1[[#This Row],[All-time score]])/1000000000) -> 13
G38: =IFERROR(Table5[[#This Row],[Full name]],"") -> Darren Poku | H38: =_xlfn.RANK.EQ(AllTime1[[#This Row],[All-time score]],AllTime1[All-time score],0) -> 107 | I38: =_xlfn.XLOOKUP(AllTime1[[#This Row],[Name]],Table16[Name],Table16[Totals],"Error",0,1) -> 14 | J38: =IF(ISNUMBER(AllTime1[[#This Row],[All-time rank]]), AllTime1[[#This Row],[All-time rank]] + ROW(AllTime1[[#This Row],[All-time rank]])/100000, 99999 + ROW(AllTime1[[#This Row],[All-time rank]])/100000) -> 107.00038 | K38: =IF(ISNUMBER(AllTime1[[#This Row],[All-time score]]), AllTime1[[#This Row],[All-time score]] + ROW(AllTime1[[#This Row],[All-time score]])/100000000, 0 + ROW(AllTime1[[#This Row],[All-time score]])/1000000000) -> 14
G39: =IFERROR(Table5[[#This Row],[Full name]],"") -> Dikang Fu | H39: =_xlfn.RANK.EQ(AllTime1[[#This Row],[All-time score]],AllTime1[All-time score],0) -> 30 | I39: =_xlfn.XLOOKUP(AllTime1[[#This Row],[Name]],Table16[Name],Table16[Totals],"Error",0,1) -> 50 | J39: =IF(ISNUMBER(AllTime1[[#This Row],[All-time rank]]), AllTime1[[#This Row],[All-time rank]] + ROW(AllTime1[[#This Row],[All-time rank]])/100000, 99999 + ROW(AllTime1[[#This Row],[All-time rank]])/100000) -> 30.00039 | K39: =IF(ISNUMBER(AllTime1[[#This Row],[All-time score]]), AllTime1[[#This Row],[All-time score]] + ROW(AllTime1[[#This Row],[All-time score]])/100000000, 0 + ROW(AllTime1[[#This Row],[All-time score]])/1000000000) -> 50
G40: =IFERROR(Table5[[#This Row],[Full name]],"") -> Elliott Beames | H40: =_xlfn.RANK.EQ(AllTime1[[#This Row],[All-time score]],AllTime1[All-time score],0) -> 6 | I40: =_xlfn.XLOOKUP(AllTime1[[#This Row],[Name]],Table16[Name],Table16[Totals],"Error",0,1) -> 94 | J40: =IF(ISNUMBER(AllTime1[[#This Row],[All-time rank]]), AllTime1[[#This Row],[All-time rank]] + ROW(AllTime1[[#This Row],[All-time rank]])/100000, 99999 + ROW(AllTime1[[#This Row],[All-time rank]])/100000) -> 6.0004 | K40: =IF(ISNUMBER(AllTime1[[#This Row],[All-time score]]), AllTime1[[#This Row],[All-time score]] + ROW(AllTime1[[#This Row],[All-time score]])/100000000, 0 + ROW(AllTime1[[#This Row],[All-time score]])/1000000000) -> 94
...

Sheet Weekly Attendance
B1: Do not sort this table
G3: Tournament # | H3: Tournament 1 | I3: Tournament 2 | J3: Tournament 3 | K3: Tournament 4 | L3: Tournament 5 | M3: Tournament 6 | N3: Tournament 7 | O3: Tournament 8 | P3: Tournament 9 | Q3: Tournament 10 | R3: Tournament 11 | S3: Tournament 12 | T3: Tournament 13 | U3: Tournament 14 | V3: Tournament 15 | W3: Tournament 16 | X3: Tournament 17 | Y3: Tournament 18 | Z3: Tournament 19 | AA3: Tournament 20 | AB3: Tournament 21 | AC3: Tournament 22 | AD3: Tournament 23 | AE3: Tournament 24 | AF3: Tournament 25 | AG3: Tournament 26 | AH3: Tournament 27 | AI3: Tournament 28 | AJ3: Tournament 29
B4: DO NOT SORT | D4: =COUNTA(Table5[Full name]) -> 350 | G4: List size at start: | H4: 146 | I4: 198 | J4: 221 | K4: 244 | L4: 255 | M4: 266 | N4: 272 | O4: 280 | P4: 287 | Q4: 299 | R4: 303 | S4: 318 | T4: 327 | AA4: 349
B5: First name | C5: Last name | D5: Full name | E5: Player Type | F5: Membership | G5: Attendance Rate | H5: September 30, 2025 | I5: October 2, 2025 | J5: October 9, 2025 | K5: October 14, 2025 | L5: October 23, 2025 | M5: October 28, 2025 | N5: November 13, 2025 | O5: November 18, 2025 | P5: November 27, 2025 | Q5: December 2, 2025 | R5: January 27, 2026 | S5: February 3, 2026 | T5: February 5, 2026 | U5: February 10, 2026 | V5: February 12, 2026 | W5: February 24, 2026 | X5: February 26, 2026 | Y5: March 3, 2026 | Z5: March 5, 2026 | AA5: March 10, 2026 | AB5: March 12, 2026 | AC5: March 17, 2026 | AD5: March 19, 2026 | AE5: March 24, 2026 | AF5: March 26, 2026 | AG5: March 31, 2026 | AH5: April 2, 2026 | AI5: April 7, 2026 | AJ5: April 9, 2026
B6: David | C6: Ribkoff | D6: =Table5[[#This Row],[First name]]&" "&Table5[[#This Row],[Last name]] -> David Ribkoff | E6: =_xlfn.XLOOKUP(Table5[[#This Row],[Full name]],Table26[Name],Table26[Role],"Member",0,1) -> President | F6: Verified | G6: {=COUNTIF(Table5[[#This Row],[September 30, 2025]:[April 7, 2026]],"Yes")/SUMPRODUCT(--(DATEVALUE(Table5[[#Headers],[September 30, 2025]:[April 9, 2026]])<=TODAY()))} -> 0.4 | H6: No | I6: No | J6: Yes | K6: No | L6: Yes | M6: Yes | N6: Yes | O6: No | P6: No | Q6: Yes | R6: Yes | S6: No | T6: No | U6: Yes | V6: No | W6: No | X6: Yes | Y6: No | Z6: No | AA6: No | AB6: No | AC6: No | AD6: No | AE6: No | AF6: No | AG6: No | AH6: No | AI6: No | AJ6: No
B7: Ryan | C7: Chen | D7: =Table5[[#This Row],[First name]]&" "&Table5[[#This Row],[Last name]] -> Ryan Chen | E7: =_xlfn.XLOOKUP(Table5[[#This Row],[Full name]],Table26[Name],Table26[Role],"Member",0,1) -> VP Comms | F7: Verified | G7: {=COUNTIF(Table5[[#This Row],[September 30, 2025]:[April 7, 2026]],"Yes")/SUMPRODUCT(--(DATEVALUE(Table5[[#Headers],[September 30, 2025]:[April 9, 2026]])<=TODAY()))} -> 0.7 | H7: Yes | I7: Yes | J7: Yes | K7: No | L7: Yes | M7: Yes | N7: Yes | O7: Yes | P7: No | Q7: Yes | R7: Yes | S7: Yes | T7: Yes | U7: No | V7: No | W7: Yes | X7: No | Y7: Yes | Z7: Yes | AA7: No | AB7: No | AC7: No | AD7: No | AE7: No | AF7: No | AG7: No | AH7: No | AI7: No | AJ7: No
B8: Myles | C8: MacPherson | D8: =Table5[[#This Row],[First name]]&" "&Table5[[#This Row],[Last name]] -> Myles MacPherson | E8: =_xlfn.XLOOKUP(Table5[[#This Row],[Full name]],Table26[Name],Table26[Role],"Member",0,1) -> VP Events | F8: Verified | G8: {=COUNTIF(Table5[[#This Row],[September 30, 2025]:[April 7, 2026]],"Yes")/SUMPRODUCT(--(DATEVALUE(Table5[[#Headers],[September 30, 2025]:[April 9, 2026]])<=TODAY()))} -> 0.2 | H8: No | I8: No | J8: No | K8: No | L8: No | M8: No | N8: No | O8: No | P8: Yes | Q8: Yes | R8: No | S8: No | T8: No | U8: Yes | V8: No | W8: No | X8: No | Y8: Yes | Z8: No | AA8: No | AB8: No | AC8: No | AD8: No | AE8: No | AF8: No | AG8: No | AH8: No | AI8: No | AJ8: No
B9: Tyler | C9: Mah | D9: =Table5[[#This Row],[First name]]&" "&Table5[[#This Row],[Last name]] -> Tyler Mah | E9: =_xlfn.XLOOKUP(Table5[[#This Row],[Full name]],Table26[Name],Table26[Role],"Member",0,1) -> VP External | F9: Verified | G9: {=COUNTIF(Table5[[#This Row],[September 30, 2025]:[April 7, 2026]],"Yes")/SUMPRODUCT(--(DATEVALUE(Table5[[#Headers],[September 30, 2025]:[April 9, 2026]])<=TODAY()))} -> 0.25 | H9: Yes | I9: Yes | J9: No | K9: No | L9: No | M9: No | N9: Yes | O9: No | P9: No | Q9: No | R9: Yes | S9: No | T9: No | U9: No | V9: No | W9: No | X9: No | Y9: No | Z9: No | AA9: Yes | AB9: No | AC9: No | AD9: No | AE9: No | AF9: No | AG9: No | AH9: No | AI9: No | AJ9: No
B10: Nathan | C10: Fenske | D10: =Table5[[#This Row],[First name]]&" "&Table5[[#This Row],[Last name]] -> Nathan Fenske | E10: =_xlfn.XLOOKUP(Table5[[#This Row],[Full name]],Table26[Name],Table26[Role],"Member",0,1) -> VP Finance | F10: Verified | G10: {=COUNTIF(Table5[[#This Row],[September 30, 2025]:[April 7, 2026]],"Yes")/SUMPRODUCT(--(DATEVALUE(Table5[[#Headers],[September 30, 2025]:[April 9, 2026]])<=TODAY()))} -> 0.1 | H10: No | I10: No | J10: No | K10: Yes | L10: No | M10: No | N10: No | O10: No | P10: No | Q10: Yes | R10: No | S10: No | T10: No | U10: No | V10: No | W10: No | X10: No | Y10: No | Z10: No | AA10: No | AB10: No | AC10: No | AD10: No | AE10: No | AF10: No | AG10: No | AH10: No | AI10: No | AJ10: No
B11: Jackie | C11: Cai | D11: =Table5[[#This Row],[First name]]&" "&Table5[[#This Row],[Last name]] -> Jackie Cai | E11: =_xlfn.XLOOKUP(Table5[[#This Row],[Full name]],Table26[Name],Table26[Role],"Member",0,1) -> VP Projects | F11: Verified | G11: {=COUNTIF(Table5[[#This Row],[September 30, 2025]:[April 7, 2026]],"Yes")/SUMPRODUCT(--(DATEVALUE(Table5[[#Headers],[September 30, 2025]:[April 9, 2026]])<=TODAY()))} -> 0.3 | H11: Yes | I11: No | J11: No | K11: No | L11: No | M11: No | N11: Yes | O11: No | P11: Yes | Q11: No | R11: Yes | S11: No | T11: Yes | U11: No | V11: No | W11: No | X11: No | Y11: Yes | Z11: No | AA11: No | AB11: No | AC11: No | AD11: No | AE11: No | AF11: No | AG11: No | AH11: No | AI11: No | AJ11: No
B12: Edward | C12: Dong | D12: =Table5[[#This Row],[First name]]&" "&Table5[[#This Row],[Last name]] -> Edward Dong | E12: =_xlfn.XLOOKUP(Table5[[#This Row],[Full name]],Table26[Name],Table26[Role],"Member",0,1) -> Director of Events | F12: Verified | G12: {=COUNTIF(Table5[[#This Row],[September 30, 2025]:[April 7, 2026]],"Yes")/SUMPRODUCT(--(DATEVALUE(Table5[[#Headers],[September 30, 2025]:[April 9, 2026]])<=TODAY()))} -> 0.4 | H12: Yes | I12: Yes | J12: No | K12: Yes | L12: No | M12: No | N12: Yes | O12: Yes | P12: Yes | Q12: Yes | R12: No | S12: No | T12: No | U12: No | V12: No | W12: No | X12: No | Y12: No | Z12: No | AA12: Yes | AB12: No | AC12: No | AD12: No | AE12: No | AF12: No | AG12: No | AH12: No | AI12: No | AJ12: No
B13: Kaden | C13: Ali | D13: =Table5[[#This Row],[First name]]&" "&Table5[[#This Row],[Last name]] -> Kaden Ali | E13: =_xlfn.XLOOKUP(Table5[[#This Row],[Full name]],Table26[Name],Table26[Role],"Member",0,1) -> Director of Events | F13: Verified | G13: {=COUNTIF(Table5[[#This Row],[September 30, 2025]:[April 7, 2026]],"Yes")/SUMPRODUCT(--(DATEVALUE(Table5[[#Headers],[September 30, 2025]:[April 9, 2026]])<=TODAY()))} -> 0.35 | H13: Yes | I13: No | J13: No | K13: No | L13: Yes | M13: Yes | N13: Yes | O13: Yes | P13: No | Q13: Yes | R13: No | S13: No | T13: No | U13: No | V13: No | W13: Yes | X13: No | Y13: No | Z13: No | AA13: No | AB13: No | AC13: No | AD13: No | AE13: No | AF13: No | AG13: No | AH13: No | AI13: No | AJ13: No
B14: Matthew | C14: Barclay | D14: =Table5[[#This Row],[First name]]&" "&Table5[[#This Row],[Last name]] -> Matthew Barclay | E14: =_xlfn.XLOOKUP(Table5[[#This Row],[Full name]],Table26[Name],Table26[Role],"Member",0,1) -> Director of Events | F14: Verified | G14: {=COUNTIF(Table5[[#This Row],[September 30, 2025]:[April 7, 2026]],"Yes")/SUMPRODUCT(--(DATEVALUE(Table5[[#Headers],[September 30, 2025]:[April 9, 2026]])<=TODAY()))} -> 0.75 | H14: No | I14: Yes | J14: No | K14: Yes | L14: No | M14: Yes | N14: Yes | O14: Yes | P14: Yes | Q14: Yes | R14: Yes | S14: No | T14: Yes | U14: Yes | V14: Yes | W14: Yes | X14: Yes | Y14: Yes | Z14: Yes | AA14: No | AB14: No | AC14: No | AD14: No | AE14: No | AF14: No | AG14: No | AH14: No | AI14: No | AJ14: No
B15: Pavel | C15: Zykmund | D15: =Table5[[#This Row],[First name]]&" "&Table5[[#This Row],[Last name]] -> Pavel Zykmund | E15: =_xlfn.XLOOKUP(Table5[[#This Row],[Full name]],Table26[Name],Table26[Role],"Member",0,1) -> Director of Events | F15: Verified | G15: {=COUNTIF(Table5[[#This Row],[September 30, 2025]:[April 7, 2026]],"Yes")/SUMPRODUCT(--(DATEVALUE(Table5[[#Headers],[September 30, 2025]:[April 9, 2026]])<=TODAY()))} -> 0.35 | H15: Yes | I15: Yes | J15: No | K15: Yes | L15: Yes | M15: No | N15: No | O15: No | P15: No | Q15: Yes | R15: Yes | S15: No | T15: No | U15: No | V15: No | W15: No | X15: No | Y15: Yes | Z15: No | AA15: No | AB15: No | AC15: No | AD15: No | AE15: No | AF15: No | AG15: No | AH15: No | AI15: No | AJ15: No
B16: Rita | C16: Shweihat | D16: =Table5[[#This Row],[First name]]&" "&Table5[[#This Row],[Last name]] -> Rita Shweihat | E16: =_xlfn.XLOOKUP(Table5[[#This Row],[Full name]],Table26[Name],Table26[Role],"Member",0,1) -> Director of Events | F16: Verified | G16: {=COUNTIF(Table5[[#This Row],[September 30, 2025]:[April 7, 2026]],"Yes")/SUMPRODUCT(--(DATEVALUE(Table5[[#Headers],[September 30, 2025]:[April 9, 2026]])<=TODAY()))} -> 0.55 | H16: Yes | I16: No | J16: No | K16: Yes | L16: Yes | M16: Yes | N16: Yes | O16: Yes | P16: Yes | Q16: Yes | R16: Yes | S16: No | T16: No | U16: No | V16: No | W16: Yes | X16: No | Y16: Yes | Z16: No | AA16: No | AB16: No | AC16: No | AD16: No | AE16: No | AF16: No | AG16: No | AH16: No | AI16: No | AJ16: No
B17: Sam | C17: Ahn | D17: =Table5[[#This Row],[First name]]&" "&Table5[[#This Row],[Last name]] -> Sam Ahn | E17: =_xlfn.XLOOKUP(Table5[[#This Row],[Full name]],Table26[Name],Table26[Role],"Member",0,1) -> Director of Events | F17: Verified | G17: {=COUNTIF(Table5[[#This Row],[September 30, 2025]:[April 7, 2026]],"Yes")/SUMPRODUCT(--(DATEVALUE(Table5[[#Headers],[September 30, 2025]:[April 9, 2026]])<=TODAY()))} -> 1 | H17: Yes | I17: Yes | J17: Yes | K17: Yes | L17: Yes | M17: Yes | N17: Yes | O17: Yes | P17: Yes | Q17: Yes | R17: Yes | S17: Yes | T17: Yes | U17: Yes | V17: Yes | W17: Yes | X17: Yes | Y17: Yes | Z17: Yes | AA17: Yes | AB17: No | AC17: No | AD17: No | AE17: No | AF17: No | AG17: No | AH17: No | AI17: No | AJ17: No
B18: Aidan | C18: Kwong | D18: =Table5[[#This Row],[First name]]&" "&Table5[[#This Row],[Last name]] -> Aidan Kwong | E18: =_xlfn.XLOOKUP(Table5[[#This Row],[Full name]],Table26[Name],Table26[Role],"Member",0,1) -> Director of Finance | F18: Verified | G18: {=COUNTIF(Table5[[#This Row],[September 30, 2025]:[April 7, 2026]],"Yes")/SUMPRODUCT(--(DATEVALUE(Table5[[#Headers],[September 30, 2025]:[April 9, 2026]])<=TODAY()))} -> 0.75 | H18: Yes | I18: Yes | J18: Yes | K18: Yes | L18: No | M18: No | N18: Yes | O18: Yes | P18: Yes | Q18: Yes | R18: Yes | S18: Yes | T18: Yes | U18: Yes | V18: Yes | W18: No | X18: Yes | Y18: Yes | Z18: No | AA18: No | AB18: No | AC18: No | AD18: No | AE18: No | AF18: No | AG18: No | AH18: No | AI18: No | AJ18: No
B19: Eduard | C19: Zavedei | D19: =Table5[[#This Row],[First name]]&" "&Table5[[#This Row],[Last name]] -> Eduard Zavedei | E19: =_xlfn.XLOOKUP(Table5[[#This Row],[Full name]],Table26[Name],Table26[Role],"Member",0,1) -> Director of Graphics | F19: Verified | G19: {=COUNTIF(Table5[[#This Row],[September 30, 2025]:[April 7, 2026]],"Yes")/SUMPRODUCT(--(DATEVALUE(Table5[[#Headers],[September 30, 2025]:[April 9, 2026]])<=TODAY()))} -> 0.1 | H19: No | I19: Yes | J19: Yes | K19: No | L19: No | M19: No | N19: No | O19: No | P19: No | Q19: No | R19: No | T19: No | U19: No | V19: No | W19: No | X19: No | Y19: No | Z19: No | AA19: No | AB19: No | AC19: No | AD19: No | AE19: No | AF19: No | AG19: No | AH19: No | AI19: No | AJ19: No
B20: Ohemaa | C20: Acheampong | D20: =Table5[[#This Row],[First name]]&" "&Table5[[#This Row],[Last name]] -> Ohemaa Acheampong | E20: =_xlfn.XLOOKUP(Table5[[#This Row],[Full name]],Table26[Name],Table26[Role],"Member",0,1) -> Director of Graphics | F20: Verified | G20: {=COUNTIF(Table5[[#This Row],[September 30, 2025]:[April 7, 2026]],"Yes")/SUMPRODUCT(--(DATEVALUE(Table5[[#Headers],[September 30, 2025]:[April 9, 2026]])<=TODAY()))} -> 0.05 | H20: No | I20: No | J20: No | K20: No | L20: No | M20: Yes | N20: No | O20: No | P20: No | Q20: No | R20: No | S20: No | T20: No | U20: No | V20: No | W20: No | X20: No | Y20: No | Z20: No | AA20: No | AB20: No | AC20: No | AD20: No | AE20: No | AF20: No | AG20: No | AH20: No | AI20: No | AJ20: No
B21: Ben | C21: Bulyovsky | D21: =Table5[[#This Row],[First name]]&" "&Table5[[#This Row],[Last name]] -> Ben Bulyovsky | E21: =_xlfn.XLOOKUP(Table5[[#This Row],[Full name]],Table26[Name],Table26[Role],"Member",0,1) -> Director of Productions | F21: Verified | G21: {=COUNTIF(Table5[[#This Row],[September 30, 2025]:[April 7, 2026]],"Yes")/SUMPRODUCT(--(DATEVALUE(Table5[[#Headers],[September 30, 2025]:[April 9, 2026]])<=TODAY()))} -> 0.15 | H21: Yes | I21: No | J21: No | K21: Yes | L21: Yes | M21: No | N21: No | O21: No | P21: No | Q21: No | R21: No | S21: No | T21: No | U21: No | V21: No | W21: No | X21: No | Y21: No | Z21: No | AA21: No | AB21: No | AC21: No | AD21: No | AE21: No | AF21: No | AG21: No | AH21: No | AI21: No | AJ21: No
B22: Brock | C22: Suidgeest | D22: =Table5[[#This Row],[First name]]&" "&Table5[[#This Row],[Last name]] -> Brock Suidgeest | E22: =_xlfn.XLOOKUP(Table5[[#This Row],[Full name]],Table26[Name],Table26[Role],"Member",0,1) -> Director of Projects | F22: Verified | G22: {=COUNTIF(Table5[[#This Row],[September 30, 2025]:[April 7, 2026]],"Yes")/SUMPRODUCT(--(DATEVALUE(Table5[[#Headers],[September 30, 2025]:[April 9, 2026]])<=TODAY()))} -> 0.15 | H22: No | I22: No | J22: No | K22: No | L22: No | M22: No | N22: No | O22: No | P22: Yes | Q22: No | R22: No | S22: Yes | T22: No | U22: No | V22: No | W22: No | X22: Yes | Y22: No | Z22: No | AA22: No | AB22: No | AC22: No | AD22: No | AE22: No | AF22: No | AG22: No | AH22: No | AI22: No | AJ22: No
B23: Cyrus | C23: Bechtold | D23: =Table5[[#This Row],[First name]]&" "&Table5[[#This Row],[Last name]] -> Cyrus Bechtold | E23: =_xlfn.XLOOKUP(Table5[[#This Row],[Full name]],Table26[Name],Table26[Role],"Member",0,1) -> Director of Projects | F23: Verified | G23: {=COUNTIF(Table5[[#This Row],[September 30, 2025]:[April 7, 2026]],"Yes")/SUMPRODUCT(--(DATEVALUE(Table5[[#Headers],[September 30, 2025]:[April 9, 2026]])<=TODAY()))} -> 0.5 | H23: No | I23: Yes | J23: Yes | K23: No | L23: No | M23: Yes | N23: No | O23: Yes | P23: No | Q23: No | R23: Yes | S23: Yes | T23: Yes | U23: No | V23: Yes | W23: No | X23: Yes | Y23: Yes | Z23: No | AA23: No | AB23: No | AC23: No | AD23: No | AE23: No | AF23: No | AG23: No | AH23: No | AI23: No | AJ23: No
B24: Jillian | C24: Ouyang | D24: =Table5[[#This Row],[First name]]&" "&Table5[[#This Row],[Last name]] -> Jillian Ouyang | E24: =_xlfn.XLOOKUP(Table5[[#This Row],[Full name]],Table26[Name],Table26[Role],"Member",0,1) -> Director of Projects | F24: Verified | G24: {=COUNTIF(Table5[[#This Row],[September 30, 2025]:[April 7, 2026]],"Yes")/SUMPRODUCT(--(DATEVALUE(Table5[[#Headers],[September 30, 2025]:[April 9, 2026]])<=TODAY()))} -> 0.3 | H24: Yes | I24: No | J24: Yes | K24: No | L24: Yes | M24: No | N24: No | O24: No | P24: No | Q24: Yes | R24: No | S24: Yes | T24: No | U24: Yes | V24: No | W24: No | X24: No | Y24: No | Z24: No | AA24: No | AB24: No | AC24: No | AD24: No | AE24: No | AF24: No | AG24: No | AH24: No | AI24: No | AJ24: No
B25: Rohan | C25: Mandi | D25: =Table5[[#This Row],[First name]]&" "&Table5[[#This Row],[Last name]] -> Rohan Mandi | E25: =_xlfn.XLOOKUP(Table5[[#This Row],[Full name]],Table26[Name],Table26[Role],"Member",0,1) -> Director of Projects | F25: Verified | G25: {=COUNTIF(Table5[[#This Row],[September 30, 2025]:[April 7, 2026]],"Yes")/SUMPRODUCT(--(DATEVALUE(Table5[[#Headers],[September 30, 2025]:[April 9, 2026]])<=TODAY()))} -> 0.45 | H25: No | I25: Yes | J25: No | K25: Yes | L25: No | M25: Yes | N25: No | O25: Yes | P25: No | Q25: Yes | R25: No | S25: No | T25: Yes | U25: Yes | V25: No | W25: No | X25: No | Y25: Yes | Z25: No | AA25: Yes | AB25: No | AC25: No | AD25: No | AE25: No | AF25: No | AG25: No | AH25: No | AI25: No | AJ25: No
B26: Ethan | C26: Kim | D26: =Table5[[#This Row],[First name]]&" "&Table5[[#This Row],[Last name]] -> Ethan Kim | E26: =_xlfn.XLOOKUP(Table5[[#This Row],[Full name]],Table26[Name],Table26[Role],"Member",0,1) -> Director of Sponsorships | F26: Verified | G26: {=COUNTIF(Table5[[#This Row],[September 30, 2025]:[April 7, 2026]],"Yes")/SUMPRODUCT(--(DATEVALUE(Table5[[#Headers],[September 30, 2025]:[April 9, 2026]])<=TODAY()))} -> 0.05 | N26: Yes | P26: No | Q26: No | R26: No | S26: No | T26: No | U26: No | V26: No | W26: No | X26: No | Y26: No | Z26: No | AA26: No | AB26: No | AC26: No | AD26: No | AE26: No | AF26: No | AG26: No | AH26: No | AI26: No | AJ26: No
B27: Kyler | C27: See | D27: =Table5[[#This Row],[First name]]&" "&Table5[[#This Row],[Last name]] -> Kyler See | E27: =_xlfn.XLOOKUP(Table5[[#This Row],[Full name]],Table26[Name],Table26[Role],"Member",0,1) -> Director of Sponsorships | F27: Verified | G27: {=COUNTIF(Table5[[#This Row],[September 30, 2025]:[April 7, 2026]],"Yes")/SUMPRODUCT(--(DATEVALUE(Table5[[#Headers],[September 30, 2025]:[April 9, 2026]])<=TODAY()))} -> 0.1 | H27: Yes | I27: No | J27: No | K27: No | L27: Yes | M27: No | N27: No | O27: No | P27: No | Q27: No | R27: No | S27: No | T27: No | U27: No | V27: No | W27: No | X27: No | Y27: No | Z27: No | AA27: No | AB27: No | AC27: No | AD27: No | AE27: No | AF27: No | AG27: No | AH27: No | AI27: No | AJ27: No
B28: Aaron | C28: Kara | D28: =Table5[[#This Row],[First name]]&" "&Table5[[#This Row],[Last name]] -> Aaron Kara | E28: =_xlfn.XLOOKUP(Table5[[#This Row],[Full name]],Table26[Name],Table26[Role],"Member",0,1) -> Executive | F28: Verified | G28: {=COUNTIF(Table5[[#This Row],[September 30, 2025]:[April 7, 2026]],"Yes")/SUMPRODUCT(--(DATEVALUE(Table5[[#Headers],[September 30, 2025]:[April 9, 2026]])<=TODAY()))} -> 0.15 | H28: Yes | I28: Yes | J28: Yes | K28: No | L28: No | M28: No | N28: No | O28: No | P28: No | Q28: No | R28: No | S28: No | T28: No | U28: No | V28: No | W28: No | X28: No | Y28: No | Z28: No | AA28: No | AB28: No | AC28: No | AD28: No | AE28: No | AF28: No | AG28: No | AH28: No | AI28: No | AJ28: No
B29: Aiden | C29: Ko | D29: =Table5[[#This Row],[First name]]&" "&Table5[[#This Row],[Last name]] -> Aiden Ko | E29: =_xlfn.XLOOKUP(Table5[[#This Row],[Full name]],Table26[Name],Table26[Role],"Member",0,1) -> Executive | F29: Verified | G29: {=COUNTIF(Table5[[#This Row],[September 30, 2025]:[April 7, 2026]],"Yes")/SUMPRODUCT(--(DATEVALUE(Table5[[#Headers],[September 30, 2025]:[April 9, 2026]])<=TODAY()))} -> 0 | H29: No | I29: No | J29: No | K29: No | L29: No | M29: No | N29: No | O29: No | P29: No | Q29: No | R29: No | S29: No | T29: No | U29: No | V29: No | W29: No | X29: No | Y29: No | Z29: No | AA29: No | AB29: No | AC29: No | AD29: No | AE29: No | AF29: No | AG29: No | AH29: No | AI29: No | AJ29: No
B30: Allen | C30: Liu | D30: =Table5[[#This Row],[First name]]&" "&Table5[[#This Row],[Last name]] -> Allen Liu | E30: =_xlfn.XLOOKUP(Table5[[#This Row],[Full name]],Table26[Name],Table26[Role],"Member",0,1) -> Executive | F30: Verified | G30: {=COUNTIF(Table5[[#This Row],[September 30, 2025]:[April 7, 2026]],"Yes")/SUMPRODUCT(--(DATEVALUE(Table5[[#Headers],[September 30, 2025]:[April 9, 2026]])<=TODAY()))} -> 0.45 | Q30: Yes | R30: Yes | S30: No | T30: Yes | U30: Yes | V30: Yes | W30: Yes | X30: Yes | Y30: Yes | Z30: No | AA30: Yes | AB30: No | AC30: No | AD30: No | AE30: No | AF30: No | AG30: No | AH30: No | AI30: No | AJ30: No
B31: Aman | C31: Bains | D31: =Table5[[#This Row],[First name]]&" "&Table5[[#This Row],[Last name]] -> Aman Bains | E31: =_xlfn.XLOOKUP(Table5[[#This Row],[Full name]],Table26[Name],Table26[Role],"Member",0,1) -> Executive | F31: Verified | G31: {=COUNTIF(Table5[[#This Row],[September 30, 2025]:[April 7, 2026]],"Yes")/SUMPRODUCT(--(DATEVALUE(Table5[[#Headers],[September 30, 2025]:[April 9, 2026]])<=TODAY()))} -> 0.05 | H31: Yes | I31: No | J31: No | K31: No | L31: No | M31: No | N31: No | O31: No | P31: No | Q31: No | R31: No | S31: No | T31: No | U31: No | V31: No | W31: No | X31: No | Y31: No | Z31: No | AA31: No | AB31: No | AC31: No | AD31: No | AE31: No | AF31: No | AG31: No | AH31: No | AI31: No | AJ31: No
B32: Anna | C32: Yu | D32: =Table5[[#This Row],[First name]]&" "&Table5[[#This Row],[Last name]] -> Anna Yu | E32: =_xlfn.XLOOKUP(Table5[[#This Row],[Full name]],Table26[Name],Table26[Role],"Member",0,1) -> Executive | F32: Verified | G32: {=COUNTIF(Table5[[#This Row],[September 30, 2025]:[April 7, 2026]],"Yes")/SUMPRODUCT(--(DATEVALUE(Table5[[#Headers],[September 30, 2025]:[April 9, 2026]])<=TODAY()))} -> 0.85 | H32: Yes | I32: Yes | J32: Yes | K32: Yes | L32: No | M32: Yes | N32: Yes | O32: Yes | P32: Yes | Q32: Yes | R32: Yes | S32: Yes | T32: Yes | U32: Yes | V32: Yes | W32: No | X32: No | Y32: Yes | Z32: Yes | AA32: Yes | AB32: No | AC32: No | AD32: No | AE32: No | AF32: No | AG32: No | AH32: No | AI32: No | AJ32: No
B33: Carson | C33: Cull | D33: =Table5[[#This Row],[First name]]&" "&Table5[[#This Row],[Last name]] -> Carson Cull | E33: =_xlfn.XLOOKUP(Table5[[#This Row],[Full name]],Table26[Name],Table26[Role],"Member",0,1) -> Executive | F33: Verified | G33: {=COUNTIF(Table5[[#This Row],[September 30, 2025]:[April 7, 2026]],"Yes")/SUMPRODUCT(--(DATEVALUE(Table5[[#Headers],[September 30, 2025]:[April 9, 2026]])<=TODAY()))} -> 0.45 | H33: No | I33: No | J33: Yes | K33: No | L33: No | M33: No | N33: Yes | O33: Yes | P33: Yes | Q33: Yes | R33: No | S33: Yes | T33: Yes | U33: No | V33: No | W33: No | X33: No | Y33: Yes | Z33: No | AA33: Yes | AB33: No | AC33: No | AD33: No | AE33: No | AF33: No | AG33: No | AH33: No | AI33: No | AJ33: No
B34: Cole | C34: Eisen | D34: =Table5[[#This Row],[First name]]&" "&Table5[[#This Row],[Last name]] -> Cole Eisen | E34: =_xlfn.XLOOKUP(Table5[[#This Row],[Full name]],Table26[Name],Table26[Role],"Member",0,1) -> Executive | F34: Verified | G34: {=COUNTIF(Table5[[#This Row],[September 30, 2025]:[April 7, 2026]],"Yes")/SUMPRODUCT(--(DATEVALUE(Table5[[#Headers],[September 30, 2025]:[April 9, 2026]])<=TODAY()))} -> 0.15 | H34: Yes | I34: Yes | J34: No | K34: No | L34: Yes | M34: No | N34: No | O34: No | P34: No | Q34: No | R34: No | S34: No | T34: No | U34: No | V34: No | W34: No | X34: No | Y34: No | Z34: No | AA34: No | AB34: No | AC34: No | AD34: No | AE34: No | AF34: No | AG34: No | AH34: No | AI34: No | AJ34: No
B35: Cole | C35: Korchinski | D35: =Table5[[#This Row],[First name]]&" "&Table5[[#This Row],[Last name]] -> Cole Korchinski | E35: =_xlfn.XLOOKUP(Table5[[#This Row],[Full name]],Table26[Name],Table26[Role],"Member",0,1) -> Executive | F35: Verified | G35: {=COUNTIF(Table5[[#This Row],[September 30, 2025]:[April 7, 2026]],"Yes")/SUMPRODUCT(--(DATEVALUE(Table5[[#Headers],[September 30, 2025]:[April 9, 2026]])<=TODAY()))} -> 0.3 | H35: Yes | I35: Yes | J35: No | K35: No | L35: Yes | M35: No | N35: No | O35: No | P35: Yes | Q35: No | R35: No | S35: No | T35: No | U35: No | V35: No | W35: No | X35: Yes | Y35: Yes | Z35: No | AA35: No | AB35: No | AC35: No | AD35: No | AE35: No | AF35: No | AG35: No | AH35: No | AI35: No | AJ35: No
B36: Damon | C36: Deng | D36: =Table5[[#This Row],[First name]]&" "&Table5[[#This Row],[Last name]] -> Damon Deng | E36: =_xlfn.XLOOKUP(Table5[[#This Row],[Full name]],Table26[Name],Table26[Role],"Member",0,1) -> Executive | F36: Verified | G36: {=COUNTIF(Table5[[#This Row],[September 30, 2025]:[April 7, 2026]],"Yes")/SUMPRODUCT(--(DATEVALUE(Table5[[#Headers],[September 30, 2025]:[April 9, 2026]])<=TODAY()))} -> 0.25 | H36: Yes | I36: No | J36: No | K36: No | L36: No | M36: No | N36: No | O36: No | P36: No | Q36: No | R36: Yes | S36: No | T36: No | U36: Yes | V36: Yes | W36: No | X36: No | Y36: No | Z36: Yes | AA36: No | AB36: No | AC36: No | AD36: No | AE36: No | AF36: No | AG36: No | AH36: No | AI36: No | AJ36: No
B37: Daniel | C37: Dillabough | D37: =Table5[[#This Row],[First name]]&" "&Table5[[#This Row],[Last name]] -> Daniel Dillabough | E37: =_xlfn.XLOOKUP(Table5[[#This Row],[Full name]],Table26[Name],Table26[Role],"Member",0,1) -> Executive | F37: Verified | G37: {=COUNTIF(Table5[[#This Row],[September 30, 2025]:[April 7, 2026]],"Yes")/SUMPRODUCT(--(DATEVALUE(Table5[[#Headers],[September 30, 2025]:[April 9, 2026]])<=TODAY()))} -> 0.45 | H37: Yes | I37: Yes | J37: No | K37: Yes | L37: Yes | M37: No | N37: Yes | O37: No | P37: Yes | Q37: Yes | R37: No | S37: No | T37: Yes | U37: No | V37: Yes | W37: No | X37: No | Y37: No | Z37: No | AA37: No | AB37: No | AC37: No | AD37: No | AE37: No | AF37: No | AG37: No | AH37: No | AI37: No | AJ37: No
B38: Darren | C38: Poku | D38: =Table5[[#This Row],[First name]]&" "&Table5[[#This Row],[Last name]] -> Darren Poku | E38: =_xlfn.XLOOKUP(Table5[[#This Row],[Full name]],Table26[Name],Table26[Role],"Member",0,1) -> Executive | F38: Verified | G38: {=COUNTIF(Table5[[#This Row],[September 30, 2025]:[April 7, 2026]],"Yes")/SUMPRODUCT(--(DATEVALUE(Table5[[#Headers],[September 30, 2025]:[April 9, 2026]])<=TODAY()))} -> 0.2 | H38: No | I38: Yes | J38: Yes | K38: No | L38: No | M38: Yes | N38: No | O38: No | P38: No | Q38: No | R38: No | S38: No | T38: No | U38: No | V38: No | W38: No | X38: No | Y38: Yes | Z38: No | AA38: No | AB38: No | AC38: No | AD38: No | AE38: No | AF38: No | AG38: No | AH38: No | AI38: No | AJ38: No
B39: Dikang | C39: Fu | D39: =Table5[[#This Row],[First name]]&" "&Table5[[#This Row],[Last name]] -> Dikang Fu | E39: =_xlfn.XLOOKUP(Table5[[#This Row],[Full name]],Table26[Name],Table26[Role],"Member",0,1) -> Executive | F39: Verified | G39: {=COUNTIF(Table5[[#This Row],[September 30, 2025]:[April 7, 2026]],"Yes")/SUMPRODUCT(--(DATEVALUE(Table5[[#Headers],[September 30, 2025]:[April 9, 2026]])<=TODAY()))} -> 0.8 | H39: Yes | I39: Yes | J39: Yes | K39: Yes | L39: No | M39: Yes | N39: Yes | O39: Yes | P39: Yes | Q39: No | R39: No | S39: Yes | T39: Yes | U39: Yes | V39: Yes | W39: Yes | X39: No | Y39: Yes | Z39: Yes | AA39: Yes | AB39: No | AC39: No | AD39: No | AE39: No | AF39: No | AG39: No | AH39: No | AI39: No | AJ39: No
B40: Elliott | C40: Beames | D40: =Table5[[#This Row],[First name]]&" "&Table5[[#This Row],[Last name]] -> Elliott Beames | E40: =_xlfn.XLOOKUP(Table5[[#This Row],[Full name]],Table26[Name],Table26[Role],"Member",0,1) -> Executive | F40: Verified | G40: {=COUNTIF(Table5[[#This Row],[September 30, 2025]:[April 7, 2026]],"Yes")/SUMPRODUCT(--(DATEVALUE(Table5[[#Headers],[September 30, 2025]:[April 9, 2026]])<=TODAY()))} -> 0.8 | H40: No | I40: No | J40: No | K40: No | L40: Yes | M40: Yes | N40: Yes | O40: Yes | P40: Yes | Q40: Yes | R40: Yes | S40: Yes | T40: Yes | U40: Yes | V40: Yes | W40: Yes | X40: Yes | Y40: Yes | Z40: Yes | AA40: Yes | AB40: No | AC40: No | AD40: No | AE40: No | AF40: No | AG40: No | AH40: No | AI40: No | AJ40: No
B41: Emma | C41: Sproxton | D41: =Table5[[#This Row],[First name]]&" "&Table5[[#This Row],[Last name]] -> Emma Sproxton | E41: =_xlfn.XLOOKUP(Table5[[#This Row],[Full name]],Table26[Name],Table26[Role],"Member",0,1) -> Executive | F41: Verified | G41: {=COUNTIF(Table5[[#This Row],[September 30, 2025]:[April 7, 2026]],"Yes")/SUMPRODUCT(--(DATEVALUE(Table5[[#Headers],[September 30, 2025]:[April 9, 2026]])<=TODAY()))} -> 0.4 | H41: No | I41: No | J41: No | K41: Yes | L41: No | M41: No | N41: No | O41: No | P41: No | Q41: No | R41: Yes | S41: Yes | T41: Yes | U41: No | V41: Yes | W41: No | X41: Yes | Y41: Yes | Z41: Yes | AA41: No | AB41: No | AC41: No | AD41: No | AE41: No | AF41: No | AG41: No | AH41: No | AI41: No | AJ41: No
...

Sheet Sheet1
A1: Player Type | B1: Executive
A3: Row Labels | B3: Sum of Attendance Rate
A4: Aaron Kara | B4: 0.3
A5: Aiden Ko | B5: 0 | C5: N
A6: Alan Long | B6: 0.2 | C6: Y
A7: Aman Bains | B7: 0.1
A8: Anna Yu | B8: 0.9
A9: Cole Eisen | B9: 0.3
A10: Cole Korchinski | B10: 0.4
A11: Daniel Dillabough | B11: 0.7
A12: Evelyn Zhang | B12: 0.2 | C12: Y
A13: Forrest Hermary | B13: 0.6
A14: Hao Bai | B14: 0.6
A15: Himaksh Talreja | B15: 0.2
A16: James Kilfoil | B16: 0.3
A17: Jared Lipski | B17: 0.4
A18: Jayden Agarwal | B18: 0.2
A19: Matthew Barclay | B19: 0.7 | E19: Alan Long
A20: Matthew Pape | B20: 0.5 | E20: Yug | F20: Y
A21: Medet Kazbek | B21: 0.5 | E21: Kadin Broomhead | F21: Y
A22: Nathan Visentin | B22: 0.2 | E22: Evelyn Zhang | F22: Y
A23: Noah George | B23: 0.9 | E23: Owen | F23: Y
A24: Noella Or | B24: 0.6 | E24: Gregory | F24: Y
A25: Priyansh Sharma | B25: 0.9 | E25: Mason | F25: Y
A26: Quenifer Lung | B26: 0.1 | E26: Victor | F26: Y
A27: Sanjay Snaidero | B27: 0.2 | E27: Alex | F27: Y
A28: Sawyer Sanderson | B28: 0.7 | E28: Oliver | F28: Y
A29: Zach Brotman | B29: 0.3 | E29: Lawrence | F29: Y
A30: Zack Hao | B30: 0.4 | E30: Aiden Gertler | F30: Y
A31: Grand Total | B31: 11.4 | E31: Divya | F31: Y

Sheet Weekly Rankings
